<?xml version="1.0"?>
<robot xmlns:xacro="http://www.ros.org/wiki/xacro" name="barista_robot">

    <xacro:include filename="$(find barista_robot_description)/xacro/wheel.xacro"/>
    <xacro:include filename="$(find barista_robot_description)/xacro/standoff.xacro"/>
    <xacro:include filename="$(find barista_robot_description)/xacro/cup_holder_tray.xacro"/>

    <!-- Materials -->
    <material name="red">
        <color rgba="1 0 0 1"/>
    </material>
    <material name="green">
        <color rgba="0 1 0 1"/>
    </material>
    <material name="blue">
        <color rgba="0 0 1 1"/>
    </material>
    <material name="yellow">
        <color rgba="1 1 0 1"/>
    </material>
    <material name="purple">
        <color rgba="0.5 0 0.5 1"/>
    </material>
    <material name="orange">
        <color rgba="1 0.65 0 1"/>
    </material>
    <material name="black">
        <color rgba="0 0 0 1"/>
    </material>

    <!-- LINKS -->
    <!-- Main Body -->
    <link name="base_link">
        <visual>
            <geometry>
                <cylinder radius="0.178" length="0.155"/>
            </geometry>
            <material name="red"/>
        </visual>
        <collision>
            <geometry>
                <cylinder radius="0.178" length="0.155"/>
            </geometry>
        </collision>
        <inertial>
            <mass value="5.0"/>
            <origin xyz="0 0 0.0775"/>
            <inertia ixx="0.04961541666666667" ixy="0.0" ixz="0.0" iyy="0.04961541666666667" iyz="0.0" izz="0.07920999999999999"/>
        </inertial>
    </link>

    <gazebo reference="base_link">
        <material>Gazebo/DarkGrey</material>
    </gazebo>

    <!-- Wheels -->
    <!-- Wheel Left -->
    <xacro:wheel wheel_name="motorized_wheel_left" />

    <gazebo reference="motorized_wheel_left">
        <kp>1000000000000000000000000000.0</kp>
        <kd>1000000000000000000000000000.0</kd>
        <mu1>10.0</mu1>
        <mu2>10.0</mu2>
        <material>Gazebo/Green</material>
    </gazebo>

    <!-- Wheel Right -->
    <xacro:wheel wheel_name="motorized_wheel_right" />

    <gazebo reference="motorized_wheel_right">
        <kp>1000000000000000000000000000.0</kp>
        <kd>1000000000000000000000000000.0</kd>
        <mu1>10.0</mu1>
        <mu2>10.0</mu2>
        <material>Gazebo/Green</material>
    </gazebo>

<!-- Caster Wheels -->
    <!-- Caster Wheel Front -->
    <link name="front_yaw_link">
      <visual>
        <origin rpy="0 1.5707 1.5707" xyz="0 0 0"/>
        <geometry>          
            <cylinder radius="0.0125000000000000005" length="0.001"/>
        </geometry>
        <material name="blue"/>
      </visual>

      <collision>
        <origin rpy="0 1.5707 1.5707" xyz="0 0 0"/>
        <geometry>
            <cylinder radius="0.0125000000000000005" length="0.001"/>
        </geometry>
      </collision>

      <inertial>
          <origin rpy="0 1.5707 1.5707" xyz="0 0 0"/>
          <mass value="0.001"/>
          <inertia ixx="3.914583333333334e-08" ixy="0" ixz="0" iyy="3.914583333333334e-08" iyz="0" izz="7.812500000000002e-08"/>
      </inertial>
    </link>

    <gazebo reference="front_yaw_link">
        <material>Gazebo/Blue</material>
    </gazebo>

    <link name="front_roll_link">
        <visual>
            <origin rpy="0 1.5707 1.5707" xyz="0 0 0"/>
            <geometry>
                <cylinder radius="0.0125000000000000005" length="0.001"/>
            </geometry>
            <material name="purple"/>
        </visual>

        <collision>
            <origin rpy="0 1.5707 1.5707" xyz="0 0 0"/>
            <geometry>
                <cylinder radius="0.0125000000000000005" length="0.001"/>
            </geometry>
        </collision>

        <inertial>
            <origin rpy="0 1.5707 1.5707" xyz="0 0 0"/>
            <mass value="0.001"/>
          <inertia ixx="3.914583333333334e-08" ixy="0" ixz="0" iyy="3.914583333333334e-08" iyz="0" izz="7.812500000000002e-08"/>
        </inertial>
    </link>

    <gazebo reference="front_roll_link">
        <material>Gazebo/Red</material>
    </gazebo>


    <link name="front_pitch_link">
        <visual>
        <origin rpy="0 1.5707 1.5707" xyz="0 0 0"/>
        <geometry>
            <sphere radius="0.0252"/>
        </geometry>
        <material name="green"/>
        </visual>

        <collision>
        <origin rpy="0 1.5707 1.5707" xyz="0 0 0"/>
        <geometry>
            <sphere radius="0.0252"/>
        </geometry>
        </collision>

        <inertial>
            <origin rpy="0 1.5707 1.5707" xyz="0 0 0"/>
            <mass value="0.1"/>
            <inertia ixx="2.5401600000000004e-05" ixy="0" ixz="0" iyy="2.5401600000000004e-05" iyz="0" izz="2.5401600000000004e-05"/>
        </inertial>
    </link>

    <gazebo reference="front_pitch_link">
        <kp>1000000000000000000000000000.0</kp>
        <kd>1000000000000000000000000000.0</kd>
        <mu1>0.5</mu1>
        <mu2>0.5</mu2>
        <material>Gazebo/Purple</material>
    </gazebo>

    <!-- Caster Wheel Back -->
    <link name="back_yaw_link">
        <visual>
            <origin rpy="0 1.5707 1.5707" xyz="0 0 0"/>
            <geometry>
                <cylinder radius="0.0125000000000000005" length="0.001"/>
            </geometry>
            <material name="blue"/>
        </visual>

        <collision>
            <origin rpy="0 1.5707 1.5707" xyz="0 0 0"/>
            <geometry>
                <cylinder radius="0.0125000000000000005" length="0.001"/>
            </geometry>
        </collision>

        <inertial>
            <origin rpy="0 1.5707 1.5707" xyz="0 0 0"/>
            <mass value="0.001"/>
            <inertia ixx="3.914583333333334e-08" ixy="0" ixz="0" iyy="3.914583333333334e-08" iyz="0" izz="7.812500000000002e-08"/>
        </inertial>
    </link>

    <gazebo reference="back_yaw_link">
        <material>Gazebo/Blue</material>
    </gazebo>

    <link name="back_roll_link">
        <visual>
            <origin rpy="0 1.5707 1.5707" xyz="0 0 0"/>
            <geometry>
                <cylinder radius="0.0125000000000000005" length="0.001"/>
            </geometry>
            <material name="red"/>
        </visual>

        <collision>
            <origin rpy="0 1.5707 1.5707" xyz="0 0 0"/>
            <geometry>
                <cylinder radius="0.0125000000000000005" length="0.001"/>
            </geometry>
        </collision>

        <inertial>
            <origin rpy="0 1.5707 1.5707" xyz="0 0 0"/>
            <mass value="0.001"/>
            <inertia ixx="3.914583333333334e-08" ixy="0" ixz="0" iyy="3.914583333333334e-08" iyz="0" izz="7.812500000000002e-08"/>
        </inertial>
    </link>

    <gazebo reference="back_roll_link">
        <material>Gazebo/Red</material>
    </gazebo>

    <link name="back_pitch_link">
        <visual>
        <origin rpy="0 1.5707 1.5707" xyz="0 0 0"/>
        <geometry>
            <sphere radius="0.0252"/>
        </geometry>
        <material name="purple"/>
        </visual>

        <collision>
            <origin rpy="0 1.5707 1.5707" xyz="0 0 0"/>
            <geometry>
                <sphere radius="0.0252"/>
            </geometry>
        </collision>

        <inertial>
            <origin rpy="0 1.5707 1.5707" xyz="0 0 0"/>
            <mass value="0.1"/>
            <inertia ixx="2.5401600000000004e-05" ixy="0" ixz="0" iyy="2.5401600000000004e-05" iyz="0" izz="2.5401600000000004e-05"/>
        </inertial>
    </link>

    <gazebo reference="back_pitch_link">
        <kp>1000000000000000000000000000.0</kp>
        <kd>1000000000000000000000000000.0</kd>
        <mu1>0.5</mu1>
        <mu2>0.5</mu2>
        <material>Gazebo/Yellow</material>
    </gazebo>

    <xacro:standoff_rod standoff_rod_name="standoff_rod_1" />

    <gazebo reference="standoff_rod_1">
        <material>Gazebo/Black</material>
    </gazebo>


    <xacro:standoff_rod standoff_rod_name="standoff_rod_2" />

    <gazebo reference="standoff_rod_2">
        <material>Gazebo/Black</material>
    </gazebo>


    <xacro:standoff_rod standoff_rod_name="standoff_rod_3" />

    <gazebo reference="standoff_rod_3">
        <material>Gazebo/Black</material>
    </gazebo>

    <xacro:standoff_rod standoff_rod_name="standoff_rod_4" />

    <gazebo reference="standoff_rod_4">
        <material>Gazebo/Black</material>
    </gazebo>

   <xacro:cup_holder_tray cup_holder_tray_name="cup_holder_tray" />

    <gazebo reference="cup_holder_tray">
        <material>Gazebo/Blue</material>
    </gazebo>



<!-- JOINTS -->
    <!-- Motorized Wheels -->
    <joint name="base_to_wheel_left" type="continuous">
        <parent link="base_link"/>
        <child link="motorized_wheel_left"/>
        <origin rpy="0 0 0" xyz="0 0.128 -0.067"/>
        <axis xyz="0 1 0"/>
        <limit effort="1.0" velocity="10.0"/>
        <dynamics damping="0.1" friction="0.1"/>
    </joint>

    <joint name="base_to_wheel_right" type="continuous">
        <parent link="base_link"/>
        <child link="motorized_wheel_right"/>
        <origin rpy="0 0 0" xyz="0 -0.128 -0.067"/>
        <axis xyz="0 1 0"/>
        <limit effort="1.0" velocity="10.0"/>
        <dynamics damping="0.1" friction="0.1"/>
    </joint>

    <!-- Caster Wheels -->
    <joint name="front_yaw_joint" type="continuous">
        <parent link="base_link" />
        <child link="front_yaw_link" />
        <origin rpy="0 0 0" xyz="0.128 0 -0.077" />
        <axis xyz="0 0 1" />
        <limit effort="1000.0" velocity="100.0" />
        <dynamics damping="0.0" friction="0.1"/>
    </joint>

    <joint name="front_roll_joint" type="continuous">
        <parent link="front_yaw_link" />
        <child link="front_roll_link" />
        <origin rpy="0 0 0" xyz="0 0 0" />
        <axis xyz="1 0 0" />
        <limit effort="1000.0" velocity="100.0" />
        <dynamics damping="0.0" friction="0.1"/>
    </joint>

    <joint name="front_pitch_joint" type="continuous">
        <parent link="front_roll_link" />
        <child link="front_pitch_link" />
        <origin rpy="0 0 0" xyz="0 0 0" />
        <axis xyz="0 1 0" />
        <limit effort="1000.0" velocity="100.0" />
        <dynamics damping="0.0" friction="0.1"/>
    </joint>


    <joint name="back_yaw_joint" type="continuous">
        <parent link="base_link" />
        <child link="back_yaw_link" />
        <origin rpy="0 0 0" xyz="-0.128 0 -0.077" />
        <axis xyz="0 0 1" />
        <limit effort="1000.0" velocity="100.0" />
        <dynamics damping="0.0" friction="0.1"/>
    </joint>

    <joint name="back_roll_joint" type="continuous">
        <parent link="back_yaw_link" />
        <child link="back_roll_link" />
        <origin rpy="0 0 0" xyz="0 0 0" />
        <axis xyz="1 0 0" />
        <limit effort="1000.0" velocity="100.0" />
        <dynamics damping="0.0" friction="0.1"/>
    </joint>

    <joint name="back_pitch_joint" type="continuous">
        <parent link="back_roll_link" />
        <child link="back_pitch_link" />
        <origin rpy="0 0 0" xyz="0 0 0" />
        <axis xyz="0 1 0" />
        <limit effort="1000.0" velocity="100.0" />
        <dynamics damping="0.0" friction="0.1"/>
    </joint>

    <!-- Standoff Rods -->
    <joint name="base_to_standoff_rod_1" type="fixed">
        <parent link="base_link"/>
        <child link="standoff_rod_1"/>
        <origin xyz="0.05 0.138 0.165" rpy="0 0 0"/>
    </joint>

    <joint name="base_to_standoff_rod_2" type="fixed">
        <parent link="base_link"/>
        <child link="standoff_rod_2"/>
        <origin xyz="-0.05 0.138 0.165" rpy="0 0 0"/>
    </joint>

    <joint name="base_to_standoff_rod_3" type="fixed">
        <parent link="base_link"/>
        <child link="standoff_rod_3"/>
        <origin xyz="0.05 -0.138 0.165" rpy="0 0 0"/>
    </joint>

    <joint name="base_to_standoff_rod_4" type="fixed">
        <parent link="base_link"/>
        <child link="standoff_rod_4"/>
        <origin xyz="-0.05 -0.138 0.165" rpy="0 0 0"/>
    </joint>

    <joint name="base_to_cup_holder_tray" type="fixed">
        <parent link="base_link"/>
        <child link="cup_holder_tray"/>
        <origin xyz="0 0 0.3025" rpy="0 0 0"/>
    </joint>


<!-- PLUGINS -->
    <!-- JOINT PUBLISHER -->
    <gazebo>
        <plugin name="barista_robot_joint_state_publisher" filename="libgazebo_ros_joint_state_publisher.so">
            <ros>
                <remapping>~/out:=joint_states</remapping>
            </ros>
            <update_rate>30</update_rate>

            <joint_name>base_to_wheel_left</joint_name>
            <joint_name>base_to_wheel_right</joint_name>
            <joint_name>front_yaw_joint</joint_name>
            <joint_name>back_yaw_joint</joint_name>
            <joint_name>front_roll_joint</joint_name>
            <joint_name>back_roll_joint</joint_name>
            <joint_name>front_pitch_joint</joint_name>
            <joint_name>back_pitch_joint</joint_name>
        </plugin>
    </gazebo>

    <!-- Differential drive -->
    <gazebo>
        <plugin name="differential_drive_controller" filename="libgazebo_ros_diff_drive.so">

        <!-- wheels -->
        <left_joint>base_to_wheel_left</left_joint>
        <right_joint>base_to_wheel_right</right_joint>

        <!-- kinematics -->
        <wheel_separation>0.256</wheel_separation>
        <wheel_diameter>0.0704</wheel_diameter>

        <!-- limits -->
        <max_wheel_torque>4.0</max_wheel_torque>
        <max_wheel_acceleration>4.0</max_wheel_acceleration>

        <!-- output -->
        <publish_odom>true</publish_odom>
        <publish_odom_tf>true</publish_odom_tf>

        <odometry_frame>odom</odometry_frame>
        <robot_base_frame>base_link</robot_base_frame>

        </plugin>
    </gazebo>

    <!-- This plugin simulates the laser scanner sensor in Gazebo and publishes LaserScan data -->
    <!-- Define the property for include_laser -->
    <xacro:property name="include_laser" value="true"/>
    <!-- Macro for the laser scanner sensor -->
    <xacro:macro name="laser_scanner" params="include_laser:=true">
        <xacro:if value="${include_laser}">
            <!-- Laser Scanner -->
            <link name="laser_scan_link">
                <visual>
                    <origin rpy="0 0 0" xyz="0 0 0"/>
                    <geometry>
                        <mesh filename="package://barista_robot_description/meshes/LIDAR_2D_Sensor/rplidar_a2.dae" scale="1.0 1.0 1.0"/>
                    </geometry>
                </visual>
                <collision>
                    <origin rpy="0 0 0" xyz="0 0 0.0204"/>
                    <geometry>
                        <cylinder length="0.0408" radius="0.037493"/>
                    </geometry>
                </collision>
                <inertial>
                    <mass value="0.20"/>
                    <origin rpy="0 0 0" xyz="0 0 0.0204"/>
                    <inertia ixx="9.803025244999999e-05" ixy="0" ixz="0" iyy="9.803025244999999e-05" iyz="0" izz="0.00014057250489999998"/>
                </inertial>
            </link>

            <gazebo reference="laser_scan_link">
                <material>Gazebo/Black</material>
            </gazebo>

            <!-- Laser Scanner Frame for positioning the gazebo_ros_laser-->
            <link name="laser_scan_frame_link">
            </link>

            <joint name="laser_scan_link_joint" type="fixed">
                <parent link="base_link"/>
                <child link="laser_scan_link"/>
                <origin rpy="0 0 0" xyz="0 0 0.0775"/>
            </joint>

            <joint name="laser_scan_frame_joint" type="fixed">
                <parent link="laser_scan_link"/>
                <child link="laser_scan_frame_link"/>
                <origin rpy="0 0 0" xyz="0 0 0.0306"/>
            </joint>

            <gazebo reference="laser_scan_frame_link">
                <sensor name="sensor_ray" type="ray">
                    <pose>0 0 0 0 0 0</pose>
                    <ray>
                        <scan>
                            <horizontal>
                                <samples>720</samples>
                                <resolution>0.5</resolution>
                                <min_angle>-3.14</min_angle>
                                <max_angle>3.14</max_angle>
                            </horizontal>
                        </scan>
                        <range>
                            <min>0.15</min>
                            <max>12.0</max>
                        </range>
                    </ray>
                    <always_on>true</always_on>
                    <visualize>true</visualize>
                    <update_rate>30.0</update_rate>
                    <plugin name="laser" filename="libgazebo_ros_ray_sensor.so">
                        <ros>
                            <remapping>~/out:=scan</remapping>
                        </ros>
                        <output_type>sensor_msgs/LaserScan</output_type>
                    </plugin>
                </sensor>
            </gazebo>
        </xacro:if>
    </xacro:macro>

    <!-- Include the laser scanner sensor macro in the robot model -->
    <xacro:laser_scanner include_laser="${include_laser}"/>
</robot>