<?xml version="1.0"?>
<robot xmlns:xacro="http://www.ros.org/wiki/xacro" name="barista_robot">

    <xacro:include filename="$(find barista_robot_description)/xacro/barista_multiple_robot_model.gazebo.xacro" />
    <xacro:include filename="$(find barista_robot_description)/xacro/wheel.xacro"/>
    <xacro:include filename="$(find barista_robot_description)/xacro/standoff.xacro"/>
    <xacro:include filename="$(find barista_robot_description)/xacro/cup_holder_tray.xacro"/>

    
    <!-- Materials -->
    <material name="red">
        <color rgba="1 0 0 1"/>
    </material>
    <material name="green">
        <color rgba="0 1 0 1"/>
    </material>
    <material name="blue">
        <color rgba="0 0 1 1"/>
    </material>
    <material name="yellow">
        <color rgba="1 1 0 1"/>
    </material>
    <material name="purple">
        <color rgba="0.5 0 0.5 1"/>
    </material>
    <material name="orange">
        <color rgba="1 0.65 0 1"/>
    </material>
    <material name="black">
        <color rgba="0 0 0 1"/>
    </material>

    <xacro:variable_elements/>
    
    <!-- LINKS -->
    <!-- Main Body -->
    <link name="base_link">
        <visual>
            <geometry>
                <cylinder radius="0.178" length="0.155"/>
            </geometry>
            <material name="base_link"/>
        </visual>
        <collision>
            <geometry>
                <cylinder radius="0.178" length="0.155"/>
            </geometry>
        </collision>
        <inertial>
            <mass value="5.0"/>
            <origin xyz="0 0 0.0775"/>
            <inertia ixx="0.04961541666666667" ixy="0.0" ixz="0.0" iyy="0.04961541666666667" iyz="0.0" izz="0.07920999999999999"/>
        </inertial>
    </link>

    <!-- Wheels -->
    <!-- Wheel Left -->
    <xacro:wheel wheel_name="motorized_wheel_left" />

    <!-- Wheel Right -->
    <xacro:wheel wheel_name="motorized_wheel_right" />

<!-- Caster Wheels -->
    <!-- Caster Wheel Front -->
    <link name="front_yaw_link">
      <visual>
        <origin rpy="0 1.5707 1.5707" xyz="0 0 0"/>
        <geometry>          
            <cylinder radius="0.0125000000000000005" length="0.001"/>
        </geometry>
        <material name="blue"/>
      </visual>

      <collision>
        <origin rpy="0 1.5707 1.5707" xyz="0 0 0"/>
        <geometry>
            <cylinder radius="0.0125000000000000005" length="0.001"/>
        </geometry>
      </collision>

      <inertial>
          <origin rpy="0 1.5707 1.5707" xyz="0 0 0"/>
          <mass value="0.001"/>
          <inertia ixx="3.914583333333334e-08" ixy="0" ixz="0" iyy="3.914583333333334e-08" iyz="0" izz="7.812500000000002e-08"/>
      </inertial>
    </link>

    <link name="front_roll_link">
        <visual>
            <origin rpy="0 1.5707 1.5707" xyz="0 0 0"/>
            <geometry>
                <cylinder radius="0.0125000000000000005" length="0.001"/>
            </geometry>
            <material name="purple"/>
        </visual>

        <collision>
            <origin rpy="0 1.5707 1.5707" xyz="0 0 0"/>
            <geometry>
                <cylinder radius="0.0125000000000000005" length="0.001"/>
            </geometry>
        </collision>

        <inertial>
            <origin rpy="0 1.5707 1.5707" xyz="0 0 0"/>
            <mass value="0.001"/>
          <inertia ixx="3.914583333333334e-08" ixy="0" ixz="0" iyy="3.914583333333334e-08" iyz="0" izz="7.812500000000002e-08"/>
        </inertial>
    </link>

    <link name="front_pitch_link">
        <visual>
        <origin rpy="0 1.5707 1.5707" xyz="0 0 0"/>
        <geometry>
            <sphere radius="0.0252"/>
        </geometry>
        <material name="green"/>
        </visual>

        <collision>
        <origin rpy="0 1.5707 1.5707" xyz="0 0 0"/>
        <geometry>
            <sphere radius="0.0252"/>
        </geometry>
        </collision>

        <inertial>
            <origin rpy="0 1.5707 1.5707" xyz="0 0 0"/>
            <mass value="0.1"/>
            <inertia ixx="2.5401600000000004e-05" ixy="0" ixz="0" iyy="2.5401600000000004e-05" iyz="0" izz="2.5401600000000004e-05"/>
        </inertial>
    </link>

    <!-- Caster Wheel Back -->
    <link name="back_yaw_link">
        <visual>
            <origin rpy="0 1.5707 1.5707" xyz="0 0 0"/>
            <geometry>
                <cylinder radius="0.0125000000000000005" length="0.001"/>
            </geometry>
            <material name="blue"/>
        </visual>

        <collision>
            <origin rpy="0 1.5707 1.5707" xyz="0 0 0"/>
            <geometry>
                <cylinder radius="0.0125000000000000005" length="0.001"/>
            </geometry>
        </collision>

        <inertial>
            <origin rpy="0 1.5707 1.5707" xyz="0 0 0"/>
            <mass value="0.001"/>
            <inertia ixx="3.914583333333334e-08" ixy="0" ixz="0" iyy="3.914583333333334e-08" iyz="0" izz="7.812500000000002e-08"/>
        </inertial>
    </link>

    <link name="back_roll_link">
        <visual>
            <origin rpy="0 1.5707 1.5707" xyz="0 0 0"/>
            <geometry>
                <cylinder radius="0.0125000000000000005" length="0.001"/>
            </geometry>
            <material name="red"/>
        </visual>

        <collision>
            <origin rpy="0 1.5707 1.5707" xyz="0 0 0"/>
            <geometry>
                <cylinder radius="0.0125000000000000005" length="0.001"/>
            </geometry>
        </collision>

        <inertial>
            <origin rpy="0 1.5707 1.5707" xyz="0 0 0"/>
            <mass value="0.001"/>
            <inertia ixx="3.914583333333334e-08" ixy="0" ixz="0" iyy="3.914583333333334e-08" iyz="0" izz="7.812500000000002e-08"/>
        </inertial>
    </link>

    <link name="back_pitch_link">
        <visual>
        <origin rpy="0 1.5707 1.5707" xyz="0 0 0"/>
        <geometry>
            <sphere radius="0.0252"/>
        </geometry>
        <material name="purple"/>
        </visual>

        <collision>
            <origin rpy="0 1.5707 1.5707" xyz="0 0 0"/>
            <geometry>
                <sphere radius="0.0252"/>
            </geometry>
        </collision>

        <inertial>
            <origin rpy="0 1.5707 1.5707" xyz="0 0 0"/>
            <mass value="0.1"/>
            <inertia ixx="2.5401600000000004e-05" ixy="0" ixz="0" iyy="2.5401600000000004e-05" iyz="0" izz="2.5401600000000004e-05"/>
        </inertial>
    </link>


    <xacro:standoff_rod standoff_rod_name="standoff_rod_1" />

    <xacro:standoff_rod standoff_rod_name="standoff_rod_2" />

    <xacro:standoff_rod standoff_rod_name="standoff_rod_3" />

    <xacro:standoff_rod standoff_rod_name="standoff_rod_4" />

   <xacro:cup_holder_tray cup_holder_tray_name="cup_holder_tray" />

<!-- JOINTS -->
    <!-- Motorized Wheels -->
    <joint name="base_to_wheel_left" type="continuous">
        <parent link="base_link"/>
        <child link="motorized_wheel_left"/>
        <origin rpy="0 0 0" xyz="0 0.128 -0.067"/>
        <axis xyz="0 1 0"/>
        <limit effort="10000" velocity="1000"/>
        <dynamics damping="1.0" friction="1.0"/>
    </joint>

    <joint name="base_to_wheel_right" type="continuous">
        <parent link="base_link"/>
        <child link="motorized_wheel_right"/>
        <origin rpy="0 0 0" xyz="0 -0.128 -0.067"/>
        <axis xyz="0 1 0"/>
        <limit effort="10000" velocity="1000"/>
        <dynamics damping="1.0" friction="1.0"/>
    </joint>

    <!-- Caster Wheels -->
    <joint name="front_yaw_joint" type="continuous">
        <parent link="base_link" />
        <child link="front_yaw_link" />
        <origin rpy="0 0 0" xyz="0.128 0 -0.077" />
        <axis xyz="0 0 1" />
        <limit effort="1000.0" velocity="100.0" />
        <dynamics damping="0.0" friction="0.1"/>
    </joint>

    <joint name="front_roll_joint" type="continuous">
        <parent link="front_yaw_link" />
        <child link="front_roll_link" />
        <origin rpy="0 0 0" xyz="0 0 0" />
        <axis xyz="1 0 0" />
        <limit effort="1000.0" velocity="100.0" />
        <dynamics damping="0.0" friction="0.1"/>
    </joint>

    <joint name="front_pitch_joint" type="continuous">
        <parent link="front_roll_link" />
        <child link="front_pitch_link" />
        <origin rpy="0 0 0" xyz="0 0 0" />
        <axis xyz="0 1 0" />
        <limit effort="1000.0" velocity="100.0" />
        <dynamics damping="0.0" friction="0.1"/>
    </joint>

    <joint name="back_yaw_joint" type="continuous">
        <parent link="base_link" />
        <child link="back_yaw_link" />
        <origin rpy="0 0 0" xyz="-0.128 0 -0.077" />
        <axis xyz="0 0 1" />
        <limit effort="1000.0" velocity="100.0" />
        <dynamics damping="0.0" friction="0.1"/>
    </joint>

    <joint name="back_roll_joint" type="continuous">
        <parent link="back_yaw_link" />
        <child link="back_roll_link" />
        <origin rpy="0 0 0" xyz="0 0 0" />
        <axis xyz="1 0 0" />
        <limit effort="1000.0" velocity="100.0" />
        <dynamics damping="0.0" friction="0.1"/>
    </joint>

    <joint name="back_pitch_joint" type="continuous">
        <parent link="back_roll_link" />
        <child link="back_pitch_link" />
        <origin rpy="0 0 0" xyz="0 0 0" />
        <axis xyz="0 1 0" />
        <limit effort="1000.0" velocity="100.0" />
        <dynamics damping="0.0" friction="0.1"/>
    </joint>

    <!-- Standoff Rods -->
    <joint name="base_to_standoff_rod_1" type="fixed">
        <parent link="base_link"/>
        <child link="standoff_rod_1"/>
        <origin xyz="0.05 0.138 0.165" rpy="0 0 0"/>
    </joint>

    <joint name="base_to_standoff_rod_2" type="fixed">
        <parent link="base_link"/>
        <child link="standoff_rod_2"/>
        <origin xyz="-0.05 0.138 0.165" rpy="0 0 0"/>
    </joint>

    <joint name="base_to_standoff_rod_3" type="fixed">
        <parent link="base_link"/>
        <child link="standoff_rod_3"/>
        <origin xyz="0.05 -0.138 0.165" rpy="0 0 0"/>
    </joint>

    <joint name="base_to_standoff_rod_4" type="fixed">
        <parent link="base_link"/>
        <child link="standoff_rod_4"/>
        <origin xyz="-0.05 -0.138 0.165" rpy="0 0 0"/>
    </joint>

    <joint name="base_to_cup_holder_tray" type="fixed">
        <parent link="base_link"/>
        <child link="cup_holder_tray"/>
        <origin xyz="0 0 0.3025" rpy="0 0 0"/>
    </joint>

  <xacro:gazebo_elements/>

    <!-- Include the laser scanner sensor macro in the robot model -->
  <xacro:laser_scanner include_laser="${include_laser}"/>
</robot>